File: _posts/al.txt
#FILE:al.dsu
#FORMAT:NETZSCH5
#IDENTITY:1
#DECIMAL:POINT
#SEPARATOR:SEMICOLON
#MTYPE:DSC
#MSUBTYPE:
#INSTRUMENT:NETZSCH STA 449 C
#PROJECT:
#DATE/TIME:2022-3-4 10:45:16
#CORR. FILE:AL2O3-dsc-N2-40-1300-20220228-2.bsu
#LABORATORY:无机
#OPERATOR:林坚钦
#REMARK:
#SAMPLE:al2o3
#SAMPLE MASS /mg:12.600
#MATERIAL:
#REFERENCE:
#REFERENCE MASS /mg:0.000
#TYPE OF CRUCIBLE:DSC/TG pan Al2O3
#SAMPLE CRUCIBLE MASS /mg:0.000
#REFERENCE CRUCIBLE MASS /mg:0.000
#CORR. CODE:020
#EXO:+1
#RANGE:40.0/10.0(K/min)/680.0
#SEGMENT:S1/1

##Temp./°C;Time/min;DSC/(mW/mg);Mass/%;Sensit./(μV/mW)
 39.96800;0.0000e+000;-2.4843e-003;100.00000;0.75874
 42.46800;    1.05956;-6.5075e-002;100.01525;0.75977
 44.96800;    1.40272;    -0.10202;100.02091;0.76080
 47.46800;    1.68501;    -0.12751;100.02588;0.76182
 49.96800;    1.93835;    -0.14610;100.03069;0.76283
 52.46800;    2.17535;    -0.15897;100.03096;0.76383
 54.96800;    2.40272;    -0.17147;100.03611;0.76482
 57.46800;    2.62342;    -0.17932;100.03717;0.76580
 59.96800;    2.83943;    -0.18620;100.04043;0.76677
 62.46800;    3.05273;    -0.19083;100.04368;0.76772
 64.96800;    3.26494;    -0.19469;100.05241;0.76867
 67.46800;    3.47631;    -0.19711;100.05647;0.76961
 69.96800;    3.68789;    -0.19891;100.05398;0.77053
 72.46800;    3.89944;    -0.19896;100.05476;0.77145
 74.96800;    4.11232;    -0.20063;100.05714;0.77236
 77.46800;    4.32591;    -0.20064;100.05715;0.77325
 79.96800;    4.54105;    -0.20115;100.05722;0.77414
 82.46800;    4.75702;    -0.19969;100.06134;0.77501
 84.96800;    4.97324;    -0.19995;100.06114;0.77587
 87.46800;    5.18998;    -0.19944;100.06374;0.77673
 89.96800;    5.40811;    -0.19925;100.06394;0.77757
 92.46800;    5.62692;    -0.19835;100.06587;0.77840
 94.96800;    5.84767;    -0.19742;100.06666;0.77922
 97.46800;    6.07002;    -0.19619;100.06822;0.78003
 99.96800;    6.29404;    -0.19508;100.07005;0.78083
102.46800;    6.51987;    -0.19516;100.07076;0.78161
104.96800;    6.74748;    -0.19418;100.07464;0.78239
107.46800;    6.97661;    -0.19240;100.07535;0.78316
109.96800;    7.20842;    -0.19168;100.07541;0.78391
112.46800;    7.44109;    -0.19107;100.07615;0.78466
114.96800;    7.67574;    -0.19050;100.07939;0.78539
117.46800;    7.91110;    -0.19003;100.08097;0.78611
119.96800;    8.14771;    -0.18905;100.08159;0.78682
122.46800;    8.38529;    -0.18990;100.08504;0.78752
124.96800;    8.62345;    -0.18924;100.08325;0.78821
127.46800;    8.86248;    -0.18813;100.08730;0.78888
129.96800;    9.10185;    -0.18843;100.08884;0.78955
132.46800;    9.34236;    -0.18803;100.09083;0.79020
134.96800;    9.58322;    -0.18697;100.09056;0.79085
137.46800;    9.82471;    -0.18728;100.09522;0.79148
139.96800;   10.06639;    -0.18656;100.09469;0.79210
142.46800;   10.30870;    -0.18594;100.09445;0.79271
144.96800;   10.55128;    -0.18596;100.10154;0.79330
147.46800;   10.79434;    -0.18470;100.09769;0.79389
149.96800;   11.03819;    -0.18467;100.10079;0.79446
152.46800;   11.28260;    -0.18397;100.10222;0.79503
154.96800;   11.52734;    -0.18317;100.10401;0.79558
157.46800;   11.77292;    -0.18291;100.10402;0.79612
159.96800;   12.01872;    -0.18138;100.10659;0.79664
162.46800;   12.26535;    -0.18182;100.10705;0.79716
164.96800;   12.51210;    -0.18195;100.10875;0.79766
167.46800;   12.75936;    -0.18101;100.10857;0.79816
169.96800;   13.00745;    -0.18101;100.10884;0.79864
172.46800;   13.25575;    -0.18081;100.10974;0.79911
174.96800;   13.50396;    -0.17933;100.11346;0.79957
177.46800;   13.75183;    -0.17880;100.11187;0.80001
179.96800;   14.00061;    -0.17870;100.11272;0.80045
182.46800;   14.24885;    -0.17782;100.11342;0.80087
184.96800;   14.49657;    -0.17840;100.11506;0.80128
187.46800;   14.74495;    -0.17693;100.11618;0.80168
189.96800;   14.99390;    -0.17665;100.11504;0.80207
192.46800;   15.24243;    -0.17616;100.11311;0.80244
194.96800;   15.49108;    -0.17591;100.11261;0.80281
197.46800;   15.74013;    -0.17552;100.11281;0.80316
199.96800;   15.99050;    -0.17477;100.11359;0.80350
202.46800;   16.23985;    -0.17486;100.11184;0.80382
204.96800;   16.48969;    -0.17449;100.11023;0.80414
207.46800;   16.73976;    -0.17315;100.11025;0.80444
209.96800;   16.98933;    -0.17276;100.10717;0.80474
212.46800;   17.23956;    -0.17306;100.10951;0.80502
214.96800;   17.48946;    -0.17395;100.11028;0.80528
217.46800;   17.73924;    -0.17378;100.11026;0.80554
219.96800;   17.98882;    -0.17318;100.10635;0.80578
222.46800;   18.23893;    -0.17329;100.10626;0.80602
224.96800;   18.48948;    -0.17333;100.10470;0.80624
227.46800;   18.73974;    -0.17314;100.10567;0.80644
229.96800;   18.98920;    -0.17267;100.10558;0.80664
232.46800;   19.23955;    -0.17245;100.10385;0.80682
234.96800;   19.48931;    -0.17222;100.10247;0.80699
237.46800;   19.73829;    -0.17259;100.10239;0.80715
239.96800;   19.98801;    -0.17268;100.10317;0.80730
242.46800;   20.23739;    -0.17128;100.10318;0.80744
244.96800;   20.48709;    -0.17137;100.10319;0.80756
247.46800;   20.73711;    -0.17099;100.10317;0.80767
249.96800;   20.98699;    -0.16911;100.10160;0.80777
252.46800;   21.23649;    -0.16998;100.09690;0.80786
254.96800;   21.48580;    -0.16980;100.09919;0.80793
257.46800;   21.73579;    -0.16824;100.10082;0.80799
259.96800;   21.98566;    -0.16790;100.09706;0.80804
262.46800;   22.23591;    -0.16761;100.09687;0.80808
264.96800;   22.48647;    -0.16705;100.09766;0.80811
267.46800;   22.73685;    -0.16537;100.09522;0.80812
269.96800;   22.98726;    -0.16462;100.09127;0.80813
272.46800;   23.23742;    -0.16340;100.09286;0.80812
274.96800;   23.48785;    -0.16314;100.08968;0.80809
277.46800;   23.73788;    -0.16305;100.09129;0.80806
279.96800;   23.98937;    -0.16307;100.08970;0.80801
282.46800;   24.24003;    -0.16275;100.09387;0.80795
284.96800;   24.48996;    -0.16246;100.09117;0.80788
287.46800;   24.74075;    -0.16190;100.08941;0.80780
289.96800;   24.99159;    -0.16193;100.08972;0.80771
292.46800;   25.24222;    -0.16190;100.09130;0.80760
294.96800;   25.49299;    -0.16213;100.08933;0.80748
297.46800;   25.74330;    -0.16124;100.09081;0.80735
299.96800;   25.99340;    -0.16111;100.09048;0.80720
302.46800;   26.24377;    -0.16074;100.08847;0.80705
304.96800;   26.49407;    -0.16037;100.08487;0.80688
307.46800;   26.74462;    -0.16109;100.08859;0.80670
309.96800;   26.99513;    -0.15965;100.08660;0.80651
312.46800;   27.24540;    -0.15960;100.08639;0.80631
314.96800;   27.49638;    -0.15842;100.08551;0.80609
317.46800;   27.74676;    -0.15643;100.08420;0.80586
319.96800;   27.99745;    -0.15565;100.08492;0.80562
322.46800;   28.24816;    -0.15454;100.07934;0.80537
324.96800;   28.49827;    -0.15449;100.08325;0.80511
327.46800;   28.74849;    -0.15494;100.08495;0.80483
329.96800;   28.99916;    -0.15398;100.08176;0.80454
332.46800;   29.25043;    -0.15407;100.08016;0.80424
334.96800;   29.50101;    -0.15423;100.08175;0.80393
337.46800;   29.75180;    -0.15312;100.08566;0.80361
339.96800;   30.00212;    -0.15272;100.08563;0.80327
342.46800;   30.25260;    -0.15282;100.08980;0.80292
344.96800;   30.50302;    -0.15139;100.08171;0.80256
347.46800;   30.75376;    -0.15128;100.08095;0.80219
349.96800;   31.00403;    -0.14978;100.07856;0.80181
352.46800;   31.25441;    -0.14895;100.07856;0.80142
354.96800;   31.50499;    -0.14780;100.08286;0.80101
357.46800;   31.75523;    -0.14746;100.07656;0.80059
359.96800;   32.00616;    -0.14625;100.08600;0.80016
362.46800;   32.25700;    -0.14609;100.08174;0.79972
364.96800;   32.50722;    -0.14564;100.07858;0.79926
367.46800;   32.75814;    -0.14504;100.08418;0.79880
369.96800;   33.00865;    -0.14452;100.08207;0.79832
372.46800;   33.25913;    -0.14344;100.08572;0.79783
374.96800;   33.50914;    -0.14193;100.08157;0.79733
377.46800;   33.75976;    -0.14196;100.08236;0.79682
379.96800;   34.00985;    -0.14160;100.08167;0.79629
382.46800;   34.26090;    -0.14098;100.07936;0.79576
384.96800;   34.51208;    -0.14075;100.08094;0.79521
387.46800;   34.76244;    -0.13995;100.08095;0.79465
389.96800;   35.01317;    -0.14045;100.07936;0.79408
392.46800;   35.26430;    -0.13999;100.08014;0.79350
394.96800;   35.51502;    -0.14016;100.08168;0.79291
397.46800;   35.76575;    -0.14022;100.08350;0.79230
399.96800;   36.01685;    -0.13920;100.07909;0.79168
402.46800;   36.26699;    -0.13956;100.08002;0.79106
404.96800;   36.51765;    -0.13969;100.07782;0.79042
407.46800;   36.76814;    -0.13923;100.08055;0.78977
409.96800;   37.01913;    -0.13828;100.07790;0.78911
412.46800;   37.26934;    -0.13860;100.08572;0.78843
414.96800;   37.51969;    -0.13941;100.08301;0.78775
417.46800;   37.77029;    -0.13956;100.08519;0.78705
419.96800;   38.02079;    -0.13980;100.08410;0.78635
422.46800;   38.27151;    -0.14084;100.07721;0.78563
424.96800;   38.52180;    -0.14158;100.08009;0.78490
427.46800;   38.77272;    -0.14220;100.08187;0.78416
429.96800;   39.02318;    -0.14343;100.08258;0.78341
432.46800;   39.27394;    -0.14342;100.08249;0.78265
434.96800;   39.52432;    -0.14411;100.08253;0.78187
437.46800;   39.77478;    -0.14352;100.08175;0.78109
439.96800;   40.02474;    -0.14442;100.08492;0.78030
442.46800;   40.27512;    -0.14585;100.08096;0.77949
444.96800;   40.52505;    -0.14792;100.08413;0.77867
447.46800;   40.77520;    -0.14794;100.08253;0.77785
449.96800;   41.02604;    -0.14919;100.08091;0.77701
452.46800;   41.27704;    -0.15116;100.08085;0.77616
454.96800;   41.52779;    -0.15168;100.08418;0.77530
457.46800;   41.77801;    -0.15299;100.07993;0.77443
459.96800;   42.02796;    -0.15491;100.08248;0.77355
462.46800;   42.27820;    -0.15637;100.08241;0.77266
464.96800;   42.52875;    -0.15875;100.08155;0.77175
467.46800;   42.78024;    -0.15955;100.08175;0.77084
469.96800;   43.03081;    -0.16016;100.08344;0.76992
472.46800;   43.28161;    -0.16144;100.08290;0.76898
474.96800;   43.53242;    -0.16283;100.08026;0.76804
477.46800;   43.78365;    -0.16349;100.08255;0.76709
479.96800;   44.03459;    -0.16425;100.08435;0.76612
482.46800;   44.28553;    -0.16578;100.07615;0.76515
484.96800;   44.53534;    -0.16664;100.08337;0.76416
487.46800;   44.78564;    -0.16905;100.08111;0.76317
489.96800;   45.03619;    -0.16998;100.07692;0.76216
492.46800;   45.28672;    -0.17100;100.07778;0.76114
494.96800;   45.53752;    -0.17241;100.07936;0.76012
497.46800;   45.78799;    -0.17314;100.08018;0.75908
499.96800;   46.03814;    -0.17434;100.07617;0.75804
502.46800;   46.28773;    -0.17496;100.07063;0.75698
504.96800;   46.53799;    -0.17717;100.07218;0.75592
507.46800;   46.78811;    -0.17877;100.07064;0.75484
509.96800;   47.03872;    -0.18009;100.06901;0.75376
512.46800;   47.28978;    -0.18142;100.06746;0.75266
514.96800;   47.54033;    -0.18363;100.06989;0.75156
517.46800;   47.79027;    -0.18376;100.07062;0.75044
519.96800;   48.04026;    -0.18638;100.06981;0.74932
522.46800;   48.29058;    -0.18783;100.06580;0.74819
524.96800;   48.54124;    -0.19047;100.06356;0.74704
527.46800;   48.79164;    -0.19186;100.06029;0.74589
529.96800;   49.04191;    -0.19383;100.05875;0.74473
532.46800;   49.29261;    -0.19583;100.06263;0.74356
534.96800;   49.54337;    -0.19789;100.06516;0.74238
537.46800;   49.79415;    -0.19971;100.06040;0.74119
539.96800;   50.04403;    -0.20091;100.06198;0.73999
542.46800;   50.29478;    -0.20385;100.06121;0.73878
544.96800;   50.54479;    -0.20474;100.06275;0.73756
547.46800;   50.79444;    -0.20746;100.05680;0.73634
549.96800;   51.04483;    -0.20930;100.05778;0.73510
552.46800;   51.29518;    -0.21179;100.05804;0.73386
554.96800;   51.54572;    -0.21361;100.05618;0.73261
557.46800;   51.79581;    -0.21472;100.05346;0.73134
559.96800;   52.04594;    -0.21704;100.05474;0.73007
562.46800;   52.29616;    -0.21943;100.05398;0.72879
564.96800;   52.54641;    -0.22388;100.05397;0.72751
567.46800;   52.79718;    -0.22779;100.05548;0.72621
569.96800;   53.04751;    -0.24061;100.05405;0.72491
572.46800;   53.29755;    -0.30496;100.05557;0.72359
574.96800;   53.54828;    -0.40389;100.06037;0.72227
577.46800;   53.79824;    -0.48527;100.05326;0.72094
579.96800;   54.04899;    -0.51356;100.05319;0.71960
582.46800;   54.29865;    -0.50131;100.05709;0.71825
584.96800;   54.54770;    -0.50012;100.05873;0.71690
587.46800;   54.79760;    -0.51215;100.05952;0.71553
589.96800;   55.04798;    -0.53309;100.06104;0.71416
592.46800;   55.29814;    -0.55565;100.06419;0.71278
594.96800;   55.54796;    -0.57884;100.06587;0.71139
597.46800;   55.79795;    -0.60277;100.06587;0.71000
599.96800;   56.04854;    -0.62967;100.06898;0.70860
602.46800;   56.29797;    -0.65925;100.07047;0.70718
604.96800;   56.54785;    -0.69253;100.07462;0.70576
607.46800;   56.79774;    -0.73015;100.07460;0.70434
609.96800;   57.04777;    -0.77305;100.07858;0.70290
612.46800;   57.29746;    -0.82209;100.08329;0.70146
614.96800;   57.54744;    -0.87472;100.08651;0.70001
617.46800;   57.79783;    -0.93319;100.08886;0.69855
619.96800;   58.04769;    -0.99503;100.10475;0.69709
622.46800;   58.29783;    -1.06971;100.10701;0.69562
624.96800;   58.54790;    -1.15707;100.11181;0.69414
627.46800;   58.79829;    -1.24591;100.12691;0.69265
629.96800;   59.04945;    -1.33512;100.13016;0.69116
632.46800;   59.30098;    -1.44336;100.13740;0.68966
634.96800;   59.55205;    -1.57253;100.15175;0.68815
637.46800;   59.80265;    -1.70128;100.16074;0.68663
639.96800;   60.05107;    -1.00062;100.17149;0.68511
642.46800;   60.29736;    -0.62183;100.17922;0.68358
644.96800;   60.54530;    -0.46792;100.18143;0.68205
647.46800;   60.79462;    -0.40197;100.19466;0.68050
649.96800;   61.04496;    -0.37504;100.20040;0.67895
652.46800;   61.29502;    -0.36791;100.21098;0.67740
654.96800;   61.54557;    -0.36907;100.21795;0.67584
657.46800;   61.79612;    -0.37387;100.22698;0.67427
659.96800;   62.04695;    -0.37941;100.23815;0.67269
662.46800;   62.29742;    -0.38582;100.24831;0.67111
664.96800;   62.54788;    -0.39090;100.25473;0.66952
667.46800;   62.79849;    -0.39647;100.26426;0.66793
669.96800;   63.04970;    -0.40405;100.26587;0.66633